<?xml version="1.0" encoding="UTF-8"?>
<!-- Generated by org.testng.reporters.JUnitReportReporter -->
<testsuite hostname="DESKTOP-Q7DQ7NJ" failures="0" tests="9" name="testcases.LoginTestSeeker" time="7.324" errors="9" timestamp="30 Jul 2021 12:10:34 GMT">
  <testcase classname="testcases.LoginTestSeeker" name="test" time="0.711">
    <error message="Error while persisting changes." type="java.sql.SQLException">
      <![CDATA[java.sql.SQLException: Error while persisting changes.
	at net.pcal.sqlsheet.XlsConnection.close(XlsConnection.java:97)
	at testcases.LoginTestSeeker.test(LoginTestSeeker.java:64)
	at java.base/jdk.internal.reflect.NativeMethodAccessorImpl.invoke0(Native Method)
	at java.base/jdk.internal.reflect.NativeMethodAccessorImpl.invoke(NativeMethodAccessorImpl.java:78)
	at java.base/jdk.internal.reflect.DelegatingMethodAccessorImpl.invoke(DelegatingMethodAccessorImpl.java:43)
	at java.base/java.lang.reflect.Method.invoke(Method.java:567)
	at org.testng.internal.MethodInvocationHelper.invokeMethod(MethodInvocationHelper.java:85)
	at org.testng.internal.Invoker.invokeMethod(Invoker.java:639)
	at org.testng.internal.Invoker.invokeTestMethod(Invoker.java:816)
	at org.testng.internal.Invoker.invokeTestMethods(Invoker.java:1124)
	at org.testng.internal.TestMethodWorker.invokeTestMethods(TestMethodWorker.java:125)
	at org.testng.internal.TestMethodWorker.run(TestMethodWorker.java:108)
	at org.testng.TestRunner.privateRun(TestRunner.java:774)
	at org.testng.TestRunner.run(TestRunner.java:624)
	at org.testng.SuiteRunner.runTest(SuiteRunner.java:359)
	at org.testng.SuiteRunner.runSequentially(SuiteRunner.java:354)
	at org.testng.SuiteRunner.privateRun(SuiteRunner.java:312)
	at org.testng.SuiteRunner.run(SuiteRunner.java:261)
	at org.testng.SuiteRunnerWorker.runSuite(SuiteRunnerWorker.java:52)
	at org.testng.SuiteRunnerWorker.run(SuiteRunnerWorker.java:86)
	at org.testng.TestNG.runSuitesSequentially(TestNG.java:1215)
	at org.testng.TestNG.runSuitesLocally(TestNG.java:1140)
	at org.testng.TestNG.run(TestNG.java:1048)
	at org.testng.remote.AbstractRemoteTestNG.run(AbstractRemoteTestNG.java:132)
	at org.testng.remote.RemoteTestNG.initAndRun(RemoteTestNG.java:230)
	at org.testng.remote.RemoteTestNG.main(RemoteTestNG.java:76)
Caused by: java.io.FileNotFoundException: d:\corejava\Book2.xls (The process cannot access the file because it is being used by another process)
	at java.base/java.io.FileOutputStream.open0(Native Method)
	at java.base/java.io.FileOutputStream.open(FileOutputStream.java:291)
	at java.base/java.io.FileOutputStream.<init>(FileOutputStream.java:234)
	at java.base/java.io.FileOutputStream.<init>(FileOutputStream.java:184)
	at net.pcal.sqlsheet.XlsConnection.close(XlsConnection.java:93)
	... 25 more
]]>
    </error>
  </testcase> <!-- test -->
  <testcase classname="testcases.LoginTestSeeker" name="test" time="0.698">
    <error message="Error while persisting changes." type="java.sql.SQLException">
      <![CDATA[java.sql.SQLException: Error while persisting changes.
	at net.pcal.sqlsheet.XlsConnection.close(XlsConnection.java:97)
	at testcases.LoginTestSeeker.test(LoginTestSeeker.java:64)
	at java.base/jdk.internal.reflect.NativeMethodAccessorImpl.invoke0(Native Method)
	at java.base/jdk.internal.reflect.NativeMethodAccessorImpl.invoke(NativeMethodAccessorImpl.java:78)
	at java.base/jdk.internal.reflect.DelegatingMethodAccessorImpl.invoke(DelegatingMethodAccessorImpl.java:43)
	at java.base/java.lang.reflect.Method.invoke(Method.java:567)
	at org.testng.internal.MethodInvocationHelper.invokeMethod(MethodInvocationHelper.java:85)
	at org.testng.internal.Invoker.invokeMethod(Invoker.java:639)
	at org.testng.internal.Invoker.invokeTestMethod(Invoker.java:816)
	at org.testng.internal.Invoker.invokeTestMethods(Invoker.java:1124)
	at org.testng.internal.TestMethodWorker.invokeTestMethods(TestMethodWorker.java:125)
	at org.testng.internal.TestMethodWorker.run(TestMethodWorker.java:108)
	at org.testng.TestRunner.privateRun(TestRunner.java:774)
	at org.testng.TestRunner.run(TestRunner.java:624)
	at org.testng.SuiteRunner.runTest(SuiteRunner.java:359)
	at org.testng.SuiteRunner.runSequentially(SuiteRunner.java:354)
	at org.testng.SuiteRunner.privateRun(SuiteRunner.java:312)
	at org.testng.SuiteRunner.run(SuiteRunner.java:261)
	at org.testng.SuiteRunnerWorker.runSuite(SuiteRunnerWorker.java:52)
	at org.testng.SuiteRunnerWorker.run(SuiteRunnerWorker.java:86)
	at org.testng.TestNG.runSuitesSequentially(TestNG.java:1215)
	at org.testng.TestNG.runSuitesLocally(TestNG.java:1140)
	at org.testng.TestNG.run(TestNG.java:1048)
	at org.testng.remote.AbstractRemoteTestNG.run(AbstractRemoteTestNG.java:132)
	at org.testng.remote.RemoteTestNG.initAndRun(RemoteTestNG.java:230)
	at org.testng.remote.RemoteTestNG.main(RemoteTestNG.java:76)
Caused by: java.io.FileNotFoundException: d:\corejava\Book2.xls (The process cannot access the file because it is being used by another process)
	at java.base/java.io.FileOutputStream.open0(Native Method)
	at java.base/java.io.FileOutputStream.open(FileOutputStream.java:291)
	at java.base/java.io.FileOutputStream.<init>(FileOutputStream.java:234)
	at java.base/java.io.FileOutputStream.<init>(FileOutputStream.java:184)
	at net.pcal.sqlsheet.XlsConnection.close(XlsConnection.java:93)
	... 25 more
]]>
    </error>
  </testcase> <!-- test -->
  <testcase classname="testcases.LoginTestSeeker" name="test" time="0.897">
    <error message="Error while persisting changes." type="java.sql.SQLException">
      <![CDATA[java.sql.SQLException: Error while persisting changes.
	at net.pcal.sqlsheet.XlsConnection.close(XlsConnection.java:97)
	at testcases.LoginTestSeeker.test(LoginTestSeeker.java:64)
	at java.base/jdk.internal.reflect.NativeMethodAccessorImpl.invoke0(Native Method)
	at java.base/jdk.internal.reflect.NativeMethodAccessorImpl.invoke(NativeMethodAccessorImpl.java:78)
	at java.base/jdk.internal.reflect.DelegatingMethodAccessorImpl.invoke(DelegatingMethodAccessorImpl.java:43)
	at java.base/java.lang.reflect.Method.invoke(Method.java:567)
	at org.testng.internal.MethodInvocationHelper.invokeMethod(MethodInvocationHelper.java:85)
	at org.testng.internal.Invoker.invokeMethod(Invoker.java:639)
	at org.testng.internal.Invoker.invokeTestMethod(Invoker.java:816)
	at org.testng.internal.Invoker.invokeTestMethods(Invoker.java:1124)
	at org.testng.internal.TestMethodWorker.invokeTestMethods(TestMethodWorker.java:125)
	at org.testng.internal.TestMethodWorker.run(TestMethodWorker.java:108)
	at org.testng.TestRunner.privateRun(TestRunner.java:774)
	at org.testng.TestRunner.run(TestRunner.java:624)
	at org.testng.SuiteRunner.runTest(SuiteRunner.java:359)
	at org.testng.SuiteRunner.runSequentially(SuiteRunner.java:354)
	at org.testng.SuiteRunner.privateRun(SuiteRunner.java:312)
	at org.testng.SuiteRunner.run(SuiteRunner.java:261)
	at org.testng.SuiteRunnerWorker.runSuite(SuiteRunnerWorker.java:52)
	at org.testng.SuiteRunnerWorker.run(SuiteRunnerWorker.java:86)
	at org.testng.TestNG.runSuitesSequentially(TestNG.java:1215)
	at org.testng.TestNG.runSuitesLocally(TestNG.java:1140)
	at org.testng.TestNG.run(TestNG.java:1048)
	at org.testng.remote.AbstractRemoteTestNG.run(AbstractRemoteTestNG.java:132)
	at org.testng.remote.RemoteTestNG.initAndRun(RemoteTestNG.java:230)
	at org.testng.remote.RemoteTestNG.main(RemoteTestNG.java:76)
Caused by: java.io.FileNotFoundException: d:\corejava\Book2.xls (The process cannot access the file because it is being used by another process)
	at java.base/java.io.FileOutputStream.open0(Native Method)
	at java.base/java.io.FileOutputStream.open(FileOutputStream.java:291)
	at java.base/java.io.FileOutputStream.<init>(FileOutputStream.java:234)
	at java.base/java.io.FileOutputStream.<init>(FileOutputStream.java:184)
	at net.pcal.sqlsheet.XlsConnection.close(XlsConnection.java:93)
	... 25 more
]]>
    </error>
  </testcase> <!-- test -->
  <testcase classname="testcases.LoginTestSeeker" name="test" time="0.685">
    <error message="Error while persisting changes." type="java.sql.SQLException">
      <![CDATA[java.sql.SQLException: Error while persisting changes.
	at net.pcal.sqlsheet.XlsConnection.close(XlsConnection.java:97)
	at testcases.LoginTestSeeker.test(LoginTestSeeker.java:64)
	at java.base/jdk.internal.reflect.NativeMethodAccessorImpl.invoke0(Native Method)
	at java.base/jdk.internal.reflect.NativeMethodAccessorImpl.invoke(NativeMethodAccessorImpl.java:78)
	at java.base/jdk.internal.reflect.DelegatingMethodAccessorImpl.invoke(DelegatingMethodAccessorImpl.java:43)
	at java.base/java.lang.reflect.Method.invoke(Method.java:567)
	at org.testng.internal.MethodInvocationHelper.invokeMethod(MethodInvocationHelper.java:85)
	at org.testng.internal.Invoker.invokeMethod(Invoker.java:639)
	at org.testng.internal.Invoker.invokeTestMethod(Invoker.java:816)
	at org.testng.internal.Invoker.invokeTestMethods(Invoker.java:1124)
	at org.testng.internal.TestMethodWorker.invokeTestMethods(TestMethodWorker.java:125)
	at org.testng.internal.TestMethodWorker.run(TestMethodWorker.java:108)
	at org.testng.TestRunner.privateRun(TestRunner.java:774)
	at org.testng.TestRunner.run(TestRunner.java:624)
	at org.testng.SuiteRunner.runTest(SuiteRunner.java:359)
	at org.testng.SuiteRunner.runSequentially(SuiteRunner.java:354)
	at org.testng.SuiteRunner.privateRun(SuiteRunner.java:312)
	at org.testng.SuiteRunner.run(SuiteRunner.java:261)
	at org.testng.SuiteRunnerWorker.runSuite(SuiteRunnerWorker.java:52)
	at org.testng.SuiteRunnerWorker.run(SuiteRunnerWorker.java:86)
	at org.testng.TestNG.runSuitesSequentially(TestNG.java:1215)
	at org.testng.TestNG.runSuitesLocally(TestNG.java:1140)
	at org.testng.TestNG.run(TestNG.java:1048)
	at org.testng.remote.AbstractRemoteTestNG.run(AbstractRemoteTestNG.java:132)
	at org.testng.remote.RemoteTestNG.initAndRun(RemoteTestNG.java:230)
	at org.testng.remote.RemoteTestNG.main(RemoteTestNG.java:76)
Caused by: java.io.FileNotFoundException: d:\corejava\Book2.xls (The process cannot access the file because it is being used by another process)
	at java.base/java.io.FileOutputStream.open0(Native Method)
	at java.base/java.io.FileOutputStream.open(FileOutputStream.java:291)
	at java.base/java.io.FileOutputStream.<init>(FileOutputStream.java:234)
	at java.base/java.io.FileOutputStream.<init>(FileOutputStream.java:184)
	at net.pcal.sqlsheet.XlsConnection.close(XlsConnection.java:93)
	... 25 more
]]>
    </error>
  </testcase> <!-- test -->
  <testcase classname="testcases.LoginTestSeeker" name="test" time="0.732">
    <error message="Error while persisting changes." type="java.sql.SQLException">
      <![CDATA[java.sql.SQLException: Error while persisting changes.
	at net.pcal.sqlsheet.XlsConnection.close(XlsConnection.java:97)
	at testcases.LoginTestSeeker.test(LoginTestSeeker.java:64)
	at java.base/jdk.internal.reflect.NativeMethodAccessorImpl.invoke0(Native Method)
	at java.base/jdk.internal.reflect.NativeMethodAccessorImpl.invoke(NativeMethodAccessorImpl.java:78)
	at java.base/jdk.internal.reflect.DelegatingMethodAccessorImpl.invoke(DelegatingMethodAccessorImpl.java:43)
	at java.base/java.lang.reflect.Method.invoke(Method.java:567)
	at org.testng.internal.MethodInvocationHelper.invokeMethod(MethodInvocationHelper.java:85)
	at org.testng.internal.Invoker.invokeMethod(Invoker.java:639)
	at org.testng.internal.Invoker.invokeTestMethod(Invoker.java:816)
	at org.testng.internal.Invoker.invokeTestMethods(Invoker.java:1124)
	at org.testng.internal.TestMethodWorker.invokeTestMethods(TestMethodWorker.java:125)
	at org.testng.internal.TestMethodWorker.run(TestMethodWorker.java:108)
	at org.testng.TestRunner.privateRun(TestRunner.java:774)
	at org.testng.TestRunner.run(TestRunner.java:624)
	at org.testng.SuiteRunner.runTest(SuiteRunner.java:359)
	at org.testng.SuiteRunner.runSequentially(SuiteRunner.java:354)
	at org.testng.SuiteRunner.privateRun(SuiteRunner.java:312)
	at org.testng.SuiteRunner.run(SuiteRunner.java:261)
	at org.testng.SuiteRunnerWorker.runSuite(SuiteRunnerWorker.java:52)
	at org.testng.SuiteRunnerWorker.run(SuiteRunnerWorker.java:86)
	at org.testng.TestNG.runSuitesSequentially(TestNG.java:1215)
	at org.testng.TestNG.runSuitesLocally(TestNG.java:1140)
	at org.testng.TestNG.run(TestNG.java:1048)
	at org.testng.remote.AbstractRemoteTestNG.run(AbstractRemoteTestNG.java:132)
	at org.testng.remote.RemoteTestNG.initAndRun(RemoteTestNG.java:230)
	at org.testng.remote.RemoteTestNG.main(RemoteTestNG.java:76)
Caused by: java.io.FileNotFoundException: d:\corejava\Book2.xls (The process cannot access the file because it is being used by another process)
	at java.base/java.io.FileOutputStream.open0(Native Method)
	at java.base/java.io.FileOutputStream.open(FileOutputStream.java:291)
	at java.base/java.io.FileOutputStream.<init>(FileOutputStream.java:234)
	at java.base/java.io.FileOutputStream.<init>(FileOutputStream.java:184)
	at net.pcal.sqlsheet.XlsConnection.close(XlsConnection.java:93)
	... 25 more
]]>
    </error>
  </testcase> <!-- test -->
  <testcase classname="testcases.LoginTestSeeker" name="test" time="1.452">
    <error message="Error while persisting changes." type="java.sql.SQLException">
      <![CDATA[java.sql.SQLException: Error while persisting changes.
	at net.pcal.sqlsheet.XlsConnection.close(XlsConnection.java:97)
	at testcases.LoginTestSeeker.test(LoginTestSeeker.java:64)
	at java.base/jdk.internal.reflect.NativeMethodAccessorImpl.invoke0(Native Method)
	at java.base/jdk.internal.reflect.NativeMethodAccessorImpl.invoke(NativeMethodAccessorImpl.java:78)
	at java.base/jdk.internal.reflect.DelegatingMethodAccessorImpl.invoke(DelegatingMethodAccessorImpl.java:43)
	at java.base/java.lang.reflect.Method.invoke(Method.java:567)
	at org.testng.internal.MethodInvocationHelper.invokeMethod(MethodInvocationHelper.java:85)
	at org.testng.internal.Invoker.invokeMethod(Invoker.java:639)
	at org.testng.internal.Invoker.invokeTestMethod(Invoker.java:816)
	at org.testng.internal.Invoker.invokeTestMethods(Invoker.java:1124)
	at org.testng.internal.TestMethodWorker.invokeTestMethods(TestMethodWorker.java:125)
	at org.testng.internal.TestMethodWorker.run(TestMethodWorker.java:108)
	at org.testng.TestRunner.privateRun(TestRunner.java:774)
	at org.testng.TestRunner.run(TestRunner.java:624)
	at org.testng.SuiteRunner.runTest(SuiteRunner.java:359)
	at org.testng.SuiteRunner.runSequentially(SuiteRunner.java:354)
	at org.testng.SuiteRunner.privateRun(SuiteRunner.java:312)
	at org.testng.SuiteRunner.run(SuiteRunner.java:261)
	at org.testng.SuiteRunnerWorker.runSuite(SuiteRunnerWorker.java:52)
	at org.testng.SuiteRunnerWorker.run(SuiteRunnerWorker.java:86)
	at org.testng.TestNG.runSuitesSequentially(TestNG.java:1215)
	at org.testng.TestNG.runSuitesLocally(TestNG.java:1140)
	at org.testng.TestNG.run(TestNG.java:1048)
	at org.testng.remote.AbstractRemoteTestNG.run(AbstractRemoteTestNG.java:132)
	at org.testng.remote.RemoteTestNG.initAndRun(RemoteTestNG.java:230)
	at org.testng.remote.RemoteTestNG.main(RemoteTestNG.java:76)
Caused by: java.io.FileNotFoundException: d:\corejava\Book2.xls (The process cannot access the file because it is being used by another process)
	at java.base/java.io.FileOutputStream.open0(Native Method)
	at java.base/java.io.FileOutputStream.open(FileOutputStream.java:291)
	at java.base/java.io.FileOutputStream.<init>(FileOutputStream.java:234)
	at java.base/java.io.FileOutputStream.<init>(FileOutputStream.java:184)
	at net.pcal.sqlsheet.XlsConnection.close(XlsConnection.java:93)
	... 25 more
]]>
    </error>
  </testcase> <!-- test -->
  <testcase classname="testcases.LoginTestSeeker" name="test" time="0.706">
    <error message="Error while persisting changes." type="java.sql.SQLException">
      <![CDATA[java.sql.SQLException: Error while persisting changes.
	at net.pcal.sqlsheet.XlsConnection.close(XlsConnection.java:97)
	at testcases.LoginTestSeeker.test(LoginTestSeeker.java:64)
	at java.base/jdk.internal.reflect.NativeMethodAccessorImpl.invoke0(Native Method)
	at java.base/jdk.internal.reflect.NativeMethodAccessorImpl.invoke(NativeMethodAccessorImpl.java:78)
	at java.base/jdk.internal.reflect.DelegatingMethodAccessorImpl.invoke(DelegatingMethodAccessorImpl.java:43)
	at java.base/java.lang.reflect.Method.invoke(Method.java:567)
	at org.testng.internal.MethodInvocationHelper.invokeMethod(MethodInvocationHelper.java:85)
	at org.testng.internal.Invoker.invokeMethod(Invoker.java:639)
	at org.testng.internal.Invoker.invokeTestMethod(Invoker.java:816)
	at org.testng.internal.Invoker.invokeTestMethods(Invoker.java:1124)
	at org.testng.internal.TestMethodWorker.invokeTestMethods(TestMethodWorker.java:125)
	at org.testng.internal.TestMethodWorker.run(TestMethodWorker.java:108)
	at org.testng.TestRunner.privateRun(TestRunner.java:774)
	at org.testng.TestRunner.run(TestRunner.java:624)
	at org.testng.SuiteRunner.runTest(SuiteRunner.java:359)
	at org.testng.SuiteRunner.runSequentially(SuiteRunner.java:354)
	at org.testng.SuiteRunner.privateRun(SuiteRunner.java:312)
	at org.testng.SuiteRunner.run(SuiteRunner.java:261)
	at org.testng.SuiteRunnerWorker.runSuite(SuiteRunnerWorker.java:52)
	at org.testng.SuiteRunnerWorker.run(SuiteRunnerWorker.java:86)
	at org.testng.TestNG.runSuitesSequentially(TestNG.java:1215)
	at org.testng.TestNG.runSuitesLocally(TestNG.java:1140)
	at org.testng.TestNG.run(TestNG.java:1048)
	at org.testng.remote.AbstractRemoteTestNG.run(AbstractRemoteTestNG.java:132)
	at org.testng.remote.RemoteTestNG.initAndRun(RemoteTestNG.java:230)
	at org.testng.remote.RemoteTestNG.main(RemoteTestNG.java:76)
Caused by: java.io.FileNotFoundException: d:\corejava\Book2.xls (The process cannot access the file because it is being used by another process)
	at java.base/java.io.FileOutputStream.open0(Native Method)
	at java.base/java.io.FileOutputStream.open(FileOutputStream.java:291)
	at java.base/java.io.FileOutputStream.<init>(FileOutputStream.java:234)
	at java.base/java.io.FileOutputStream.<init>(FileOutputStream.java:184)
	at net.pcal.sqlsheet.XlsConnection.close(XlsConnection.java:93)
	... 25 more
]]>
    </error>
  </testcase> <!-- test -->
  <testcase classname="testcases.LoginTestSeeker" name="test" time="0.747">
    <error message="Error while persisting changes." type="java.sql.SQLException">
      <![CDATA[java.sql.SQLException: Error while persisting changes.
	at net.pcal.sqlsheet.XlsConnection.close(XlsConnection.java:97)
	at testcases.LoginTestSeeker.test(LoginTestSeeker.java:64)
	at java.base/jdk.internal.reflect.NativeMethodAccessorImpl.invoke0(Native Method)
	at java.base/jdk.internal.reflect.NativeMethodAccessorImpl.invoke(NativeMethodAccessorImpl.java:78)
	at java.base/jdk.internal.reflect.DelegatingMethodAccessorImpl.invoke(DelegatingMethodAccessorImpl.java:43)
	at java.base/java.lang.reflect.Method.invoke(Method.java:567)
	at org.testng.internal.MethodInvocationHelper.invokeMethod(MethodInvocationHelper.java:85)
	at org.testng.internal.Invoker.invokeMethod(Invoker.java:639)
	at org.testng.internal.Invoker.invokeTestMethod(Invoker.java:816)
	at org.testng.internal.Invoker.invokeTestMethods(Invoker.java:1124)
	at org.testng.internal.TestMethodWorker.invokeTestMethods(TestMethodWorker.java:125)
	at org.testng.internal.TestMethodWorker.run(TestMethodWorker.java:108)
	at org.testng.TestRunner.privateRun(TestRunner.java:774)
	at org.testng.TestRunner.run(TestRunner.java:624)
	at org.testng.SuiteRunner.runTest(SuiteRunner.java:359)
	at org.testng.SuiteRunner.runSequentially(SuiteRunner.java:354)
	at org.testng.SuiteRunner.privateRun(SuiteRunner.java:312)
	at org.testng.SuiteRunner.run(SuiteRunner.java:261)
	at org.testng.SuiteRunnerWorker.runSuite(SuiteRunnerWorker.java:52)
	at org.testng.SuiteRunnerWorker.run(SuiteRunnerWorker.java:86)
	at org.testng.TestNG.runSuitesSequentially(TestNG.java:1215)
	at org.testng.TestNG.runSuitesLocally(TestNG.java:1140)
	at org.testng.TestNG.run(TestNG.java:1048)
	at org.testng.remote.AbstractRemoteTestNG.run(AbstractRemoteTestNG.java:132)
	at org.testng.remote.RemoteTestNG.initAndRun(RemoteTestNG.java:230)
	at org.testng.remote.RemoteTestNG.main(RemoteTestNG.java:76)
Caused by: java.io.FileNotFoundException: d:\corejava\Book2.xls (The process cannot access the file because it is being used by another process)
	at java.base/java.io.FileOutputStream.open0(Native Method)
	at java.base/java.io.FileOutputStream.open(FileOutputStream.java:291)
	at java.base/java.io.FileOutputStream.<init>(FileOutputStream.java:234)
	at java.base/java.io.FileOutputStream.<init>(FileOutputStream.java:184)
	at net.pcal.sqlsheet.XlsConnection.close(XlsConnection.java:93)
	... 25 more
]]>
    </error>
  </testcase> <!-- test -->
  <testcase classname="testcases.LoginTestSeeker" name="test" time="0.696">
    <error message="Error while persisting changes." type="java.sql.SQLException">
      <![CDATA[java.sql.SQLException: Error while persisting changes.
	at net.pcal.sqlsheet.XlsConnection.close(XlsConnection.java:97)
	at testcases.LoginTestSeeker.test(LoginTestSeeker.java:64)
	at java.base/jdk.internal.reflect.NativeMethodAccessorImpl.invoke0(Native Method)
	at java.base/jdk.internal.reflect.NativeMethodAccessorImpl.invoke(NativeMethodAccessorImpl.java:78)
	at java.base/jdk.internal.reflect.DelegatingMethodAccessorImpl.invoke(DelegatingMethodAccessorImpl.java:43)
	at java.base/java.lang.reflect.Method.invoke(Method.java:567)
	at org.testng.internal.MethodInvocationHelper.invokeMethod(MethodInvocationHelper.java:85)
	at org.testng.internal.Invoker.invokeMethod(Invoker.java:639)
	at org.testng.internal.Invoker.invokeTestMethod(Invoker.java:816)
	at org.testng.internal.Invoker.invokeTestMethods(Invoker.java:1124)
	at org.testng.internal.TestMethodWorker.invokeTestMethods(TestMethodWorker.java:125)
	at org.testng.internal.TestMethodWorker.run(TestMethodWorker.java:108)
	at org.testng.TestRunner.privateRun(TestRunner.java:774)
	at org.testng.TestRunner.run(TestRunner.java:624)
	at org.testng.SuiteRunner.runTest(SuiteRunner.java:359)
	at org.testng.SuiteRunner.runSequentially(SuiteRunner.java:354)
	at org.testng.SuiteRunner.privateRun(SuiteRunner.java:312)
	at org.testng.SuiteRunner.run(SuiteRunner.java:261)
	at org.testng.SuiteRunnerWorker.runSuite(SuiteRunnerWorker.java:52)
	at org.testng.SuiteRunnerWorker.run(SuiteRunnerWorker.java:86)
	at org.testng.TestNG.runSuitesSequentially(TestNG.java:1215)
	at org.testng.TestNG.runSuitesLocally(TestNG.java:1140)
	at org.testng.TestNG.run(TestNG.java:1048)
	at org.testng.remote.AbstractRemoteTestNG.run(AbstractRemoteTestNG.java:132)
	at org.testng.remote.RemoteTestNG.initAndRun(RemoteTestNG.java:230)
	at org.testng.remote.RemoteTestNG.main(RemoteTestNG.java:76)
Caused by: java.io.FileNotFoundException: d:\corejava\Book2.xls (The process cannot access the file because it is being used by another process)
	at java.base/java.io.FileOutputStream.open0(Native Method)
	at java.base/java.io.FileOutputStream.open(FileOutputStream.java:291)
	at java.base/java.io.FileOutputStream.<init>(FileOutputStream.java:234)
	at java.base/java.io.FileOutputStream.<init>(FileOutputStream.java:184)
	at net.pcal.sqlsheet.XlsConnection.close(XlsConnection.java:93)
	... 25 more
]]>
    </error>
  </testcase> <!-- test -->
</testsuite> <!-- testcases.LoginTestSeeker -->
